[2024-03-10T14:41:19.085+0530] {taskinstance.py:1979} INFO - Dependencies all met for dep_context=non-requeueable deps ti=<TaskInstance: data_fetch_pipeline_big_data.fetch_individual_files manual__2024-03-10T09:10:41.696863+00:00 [queued]>
[2024-03-10T14:41:19.090+0530] {taskinstance.py:1979} INFO - Dependencies all met for dep_context=requeueable deps ti=<TaskInstance: data_fetch_pipeline_big_data.fetch_individual_files manual__2024-03-10T09:10:41.696863+00:00 [queued]>
[2024-03-10T14:41:19.090+0530] {taskinstance.py:2193} INFO - Starting attempt 1 of 2
[2024-03-10T14:41:19.179+0530] {taskinstance.py:2214} INFO - Executing <Task(BashOperator): fetch_individual_files> on 2024-03-10 09:10:41.696863+00:00
[2024-03-10T14:41:19.190+0530] {standard_task_runner.py:60} INFO - Started process 14074 to run task
[2024-03-10T14:41:19.196+0530] {standard_task_runner.py:87} INFO - Running: ['airflow', 'tasks', 'run', 'data_fetch_pipeline_big_data', 'fetch_individual_files', 'manual__2024-03-10T09:10:41.696863+00:00', '--job-id', '30', '--raw', '--subdir', 'DAGS_FOLDER/big_data_lab.py', '--cfg-path', '/tmp/tmpwqgk2z8e']
[2024-03-10T14:41:19.200+0530] {standard_task_runner.py:88} INFO - Job 30: Subtask fetch_individual_files
[2024-03-10T14:41:19.338+0530] {task_command.py:423} INFO - Running <TaskInstance: data_fetch_pipeline_big_data.fetch_individual_files manual__2024-03-10T09:10:41.696863+00:00 [running]> on host HP
[2024-03-10T14:41:19.455+0530] {abstractoperator.py:707} ERROR - Exception rendering Jinja template for task 'fetch_individual_files', field 'bash_command'. Template: 'bash /home/akranth/airflow/dags/task_3.sh'
Traceback (most recent call last):
  File "/home/akranth/airflow/airflow_env/lib/python3.11/site-packages/airflow/models/abstractoperator.py", line 699, in _do_render_template_fields
    rendered_content = self.render_template(
                       ^^^^^^^^^^^^^^^^^^^^^
  File "/home/akranth/airflow/airflow_env/lib/python3.11/site-packages/airflow/template/templater.py", line 171, in render_template
    template = jinja_env.get_template(value)
               ^^^^^^^^^^^^^^^^^^^^^^^^^^^^^
  File "/home/akranth/airflow/airflow_env/lib/python3.11/site-packages/jinja2/environment.py", line 1010, in get_template
    return self._load_template(name, globals)
           ^^^^^^^^^^^^^^^^^^^^^^^^^^^^^^^^^^
  File "/home/akranth/airflow/airflow_env/lib/python3.11/site-packages/jinja2/environment.py", line 969, in _load_template
    template = self.loader.load(self, name, self.make_globals(globals))
               ^^^^^^^^^^^^^^^^^^^^^^^^^^^^^^^^^^^^^^^^^^^^^^^^^^^^^^^^
  File "/home/akranth/airflow/airflow_env/lib/python3.11/site-packages/jinja2/loaders.py", line 125, in load
    source, filename, uptodate = self.get_source(environment, name)
                                 ^^^^^^^^^^^^^^^^^^^^^^^^^^^^^^^^^^
  File "/home/akranth/airflow/airflow_env/lib/python3.11/site-packages/jinja2/loaders.py", line 204, in get_source
    raise TemplateNotFound(template)
jinja2.exceptions.TemplateNotFound: bash /home/akranth/airflow/dags/task_3.sh
[2024-03-10T14:41:19.498+0530] {taskinstance.py:2728} ERROR - Task failed with exception
Traceback (most recent call last):
  File "/home/akranth/airflow/airflow_env/lib/python3.11/site-packages/airflow/models/taskinstance.py", line 2357, in _run_raw_task
    self._execute_task_with_callbacks(context, test_mode, session=session)
  File "/home/akranth/airflow/airflow_env/lib/python3.11/site-packages/airflow/models/taskinstance.py", line 2495, in _execute_task_with_callbacks
    task_orig = self.render_templates(context=context)
                ^^^^^^^^^^^^^^^^^^^^^^^^^^^^^^^^^^^^^^
  File "/home/akranth/airflow/airflow_env/lib/python3.11/site-packages/airflow/models/taskinstance.py", line 2907, in render_templates
    original_task.render_template_fields(context)
  File "/home/akranth/airflow/airflow_env/lib/python3.11/site-packages/airflow/models/baseoperator.py", line 1241, in render_template_fields
    self._do_render_template_fields(self, self.template_fields, context, jinja_env, set())
  File "/home/akranth/airflow/airflow_env/lib/python3.11/site-packages/airflow/utils/session.py", line 79, in wrapper
    return func(*args, session=session, **kwargs)
           ^^^^^^^^^^^^^^^^^^^^^^^^^^^^^^^^^^^^^^
  File "/home/akranth/airflow/airflow_env/lib/python3.11/site-packages/airflow/models/abstractoperator.py", line 699, in _do_render_template_fields
    rendered_content = self.render_template(
                       ^^^^^^^^^^^^^^^^^^^^^
  File "/home/akranth/airflow/airflow_env/lib/python3.11/site-packages/airflow/template/templater.py", line 171, in render_template
    template = jinja_env.get_template(value)
               ^^^^^^^^^^^^^^^^^^^^^^^^^^^^^
  File "/home/akranth/airflow/airflow_env/lib/python3.11/site-packages/jinja2/environment.py", line 1010, in get_template
    return self._load_template(name, globals)
           ^^^^^^^^^^^^^^^^^^^^^^^^^^^^^^^^^^
  File "/home/akranth/airflow/airflow_env/lib/python3.11/site-packages/jinja2/environment.py", line 969, in _load_template
    template = self.loader.load(self, name, self.make_globals(globals))
               ^^^^^^^^^^^^^^^^^^^^^^^^^^^^^^^^^^^^^^^^^^^^^^^^^^^^^^^^
  File "/home/akranth/airflow/airflow_env/lib/python3.11/site-packages/jinja2/loaders.py", line 125, in load
    source, filename, uptodate = self.get_source(environment, name)
                                 ^^^^^^^^^^^^^^^^^^^^^^^^^^^^^^^^^^
  File "/home/akranth/airflow/airflow_env/lib/python3.11/site-packages/jinja2/loaders.py", line 204, in get_source
    raise TemplateNotFound(template)
jinja2.exceptions.TemplateNotFound: bash /home/akranth/airflow/dags/task_3.sh
[2024-03-10T14:41:19.533+0530] {taskinstance.py:1149} INFO - Marking task as UP_FOR_RETRY. dag_id=data_fetch_pipeline_big_data, task_id=fetch_individual_files, execution_date=20240310T091041, start_date=20240310T091119, end_date=20240310T091119
[2024-03-10T14:41:19.628+0530] {standard_task_runner.py:107} ERROR - Failed to execute job 30 for task fetch_individual_files (bash /home/akranth/airflow/dags/task_3.sh; 14074)
[2024-03-10T14:41:19.647+0530] {local_task_job_runner.py:234} INFO - Task exited with return code 1
[2024-03-10T14:41:19.659+0530] {taskinstance.py:3309} INFO - 0 downstream tasks scheduled from follow-on schedule check
