[2024-03-03T16:04:26.503+0530] {taskinstance.py:1979} INFO - Dependencies all met for dep_context=non-requeueable deps ti=<TaskInstance: data_fetch_pipeline.select_random_files manual__2024-03-03T10:07:50.567651+00:00 [queued]>
[2024-03-03T16:04:26.508+0530] {taskinstance.py:1979} INFO - Dependencies all met for dep_context=requeueable deps ti=<TaskInstance: data_fetch_pipeline.select_random_files manual__2024-03-03T10:07:50.567651+00:00 [queued]>
[2024-03-03T16:04:26.508+0530] {taskinstance.py:2193} INFO - Starting attempt 1 of 2
[2024-03-03T16:04:26.596+0530] {taskinstance.py:2214} INFO - Executing <Task(PythonOperator): select_random_files> on 2024-03-03 10:07:50.567651+00:00
[2024-03-03T16:04:26.606+0530] {standard_task_runner.py:60} INFO - Started process 4073 to run task
[2024-03-03T16:04:26.611+0530] {standard_task_runner.py:87} INFO - Running: ['airflow', 'tasks', 'run', 'data_fetch_pipeline', 'select_random_files', 'manual__2024-03-03T10:07:50.567651+00:00', '--job-id', '15', '--raw', '--subdir', 'DAGS_FOLDER/assignment_2.py', '--cfg-path', '/tmp/tmpwcx6tfcn']
[2024-03-03T16:04:26.612+0530] {standard_task_runner.py:88} INFO - Job 15: Subtask select_random_files
[2024-03-03T16:04:26.738+0530] {task_command.py:423} INFO - Running <TaskInstance: data_fetch_pipeline.select_random_files manual__2024-03-03T10:07:50.567651+00:00 [running]> on host HP
[2024-03-03T16:04:26.974+0530] {taskinstance.py:2510} INFO - Exporting env vars: AIRFLOW_CTX_DAG_OWNER='airflow' AIRFLOW_CTX_DAG_ID='data_fetch_pipeline' AIRFLOW_CTX_TASK_ID='select_random_files' AIRFLOW_CTX_EXECUTION_DATE='2024-03-03T10:07:50.567651+00:00' AIRFLOW_CTX_TRY_NUMBER='1' AIRFLOW_CTX_DAG_RUN_ID='manual__2024-03-03T10:07:50.567651+00:00'
[2024-03-03T16:04:26.979+0530] {taskinstance.py:2728} ERROR - Task failed with exception
Traceback (most recent call last):
  File "/home/akranth/airflow/airflow_env/lib/python3.11/site-packages/airflow/models/taskinstance.py", line 444, in _execute_task
    result = _execute_callable(context=context, **execute_callable_kwargs)
             ^^^^^^^^^^^^^^^^^^^^^^^^^^^^^^^^^^^^^^^^^^^^^^^^^^^^^^^^^^^^^
  File "/home/akranth/airflow/airflow_env/lib/python3.11/site-packages/airflow/models/taskinstance.py", line 414, in _execute_callable
    return execute_callable(context=context, **execute_callable_kwargs)
           ^^^^^^^^^^^^^^^^^^^^^^^^^^^^^^^^^^^^^^^^^^^^^^^^^^^^^^^^^^^^
  File "/home/akranth/airflow/airflow_env/lib/python3.11/site-packages/airflow/operators/python.py", line 200, in execute
    return_value = self.execute_callable()
                   ^^^^^^^^^^^^^^^^^^^^^^^
  File "/home/akranth/airflow/airflow_env/lib/python3.11/site-packages/airflow/operators/python.py", line 217, in execute_callable
    return self.python_callable(*self.op_args, **self.op_kwargs)
           ^^^^^^^^^^^^^^^^^^^^^^^^^^^^^^^^^^^^^^^^^^^^^^^^^^^^^
  File "/home/akranth/airflow/dags/assignment_2.py", line 39, in select_random_files
    print(os.listdir(location))
          ^^^^^^^^^^^^^^^^^^^^
FileNotFoundError: [Errno 2] No such file or directory: '/home/akranth/airflow/dag/www.ncei.noaa.gov/data/local-climatological-data/access/1903/'
[2024-03-03T16:04:26.989+0530] {taskinstance.py:1149} INFO - Marking task as UP_FOR_RETRY. dag_id=data_fetch_pipeline, task_id=select_random_files, execution_date=20240303T100750, start_date=20240303T103426, end_date=20240303T103426
[2024-03-03T16:04:27.079+0530] {standard_task_runner.py:107} ERROR - Failed to execute job 15 for task select_random_files ([Errno 2] No such file or directory: '/home/akranth/airflow/dag/www.ncei.noaa.gov/data/local-climatological-data/access/1903/'; 4073)
[2024-03-03T16:04:27.105+0530] {local_task_job_runner.py:234} INFO - Task exited with return code 1
[2024-03-03T16:04:27.119+0530] {taskinstance.py:3309} INFO - 0 downstream tasks scheduled from follow-on schedule check
