[2024-03-10T13:49:43.240+0530] {taskinstance.py:1979} INFO - Dependencies all met for dep_context=non-requeueable deps ti=<TaskInstance: data_fetch_pipeline_big_data.select_random_files manual__2024-03-03T11:09:06.924388+00:00 [queued]>
[2024-03-10T13:49:43.247+0530] {taskinstance.py:1979} INFO - Dependencies all met for dep_context=requeueable deps ti=<TaskInstance: data_fetch_pipeline_big_data.select_random_files manual__2024-03-03T11:09:06.924388+00:00 [queued]>
[2024-03-10T13:49:43.247+0530] {taskinstance.py:2193} INFO - Starting attempt 2 of 2
[2024-03-10T13:49:43.421+0530] {taskinstance.py:2214} INFO - Executing <Task(PythonOperator): select_random_files> on 2024-03-03 11:09:06.924388+00:00
[2024-03-10T13:49:43.430+0530] {standard_task_runner.py:60} INFO - Started process 5711 to run task
[2024-03-10T13:49:43.435+0530] {standard_task_runner.py:87} INFO - Running: ['airflow', 'tasks', 'run', 'data_fetch_pipeline_big_data', 'select_random_files', 'manual__2024-03-03T11:09:06.924388+00:00', '--job-id', '26', '--raw', '--subdir', 'DAGS_FOLDER/big_data_lab.py', '--cfg-path', '/tmp/tmpp3iu65m0']
[2024-03-10T13:49:43.437+0530] {standard_task_runner.py:88} INFO - Job 26: Subtask select_random_files
[2024-03-10T13:49:43.564+0530] {task_command.py:423} INFO - Running <TaskInstance: data_fetch_pipeline_big_data.select_random_files manual__2024-03-03T11:09:06.924388+00:00 [running]> on host HP
[2024-03-10T13:49:43.719+0530] {taskinstance.py:2510} INFO - Exporting env vars: AIRFLOW_CTX_DAG_OWNER='airflow' AIRFLOW_CTX_DAG_ID='data_fetch_pipeline_big_data' AIRFLOW_CTX_TASK_ID='select_random_files' AIRFLOW_CTX_EXECUTION_DATE='2024-03-03T11:09:06.924388+00:00' AIRFLOW_CTX_TRY_NUMBER='2' AIRFLOW_CTX_DAG_RUN_ID='manual__2024-03-03T11:09:06.924388+00:00'
[2024-03-10T13:49:43.720+0530] {taskinstance.py:2728} ERROR - Task failed with exception
Traceback (most recent call last):
  File "/home/akranth/airflow/airflow_env/lib/python3.11/site-packages/airflow/models/taskinstance.py", line 444, in _execute_task
    result = _execute_callable(context=context, **execute_callable_kwargs)
             ^^^^^^^^^^^^^^^^^^^^^^^^^^^^^^^^^^^^^^^^^^^^^^^^^^^^^^^^^^^^^
  File "/home/akranth/airflow/airflow_env/lib/python3.11/site-packages/airflow/models/taskinstance.py", line 414, in _execute_callable
    return execute_callable(context=context, **execute_callable_kwargs)
           ^^^^^^^^^^^^^^^^^^^^^^^^^^^^^^^^^^^^^^^^^^^^^^^^^^^^^^^^^^^^
  File "/home/akranth/airflow/airflow_env/lib/python3.11/site-packages/airflow/operators/python.py", line 200, in execute
    return_value = self.execute_callable()
                   ^^^^^^^^^^^^^^^^^^^^^^^
  File "/home/akranth/airflow/airflow_env/lib/python3.11/site-packages/airflow/operators/python.py", line 217, in execute_callable
    return self.python_callable(*self.op_args, **self.op_kwargs)
           ^^^^^^^^^^^^^^^^^^^^^^^^^^^^^^^^^^^^^^^^^^^^^^^^^^^^^
  File "/home/akranth/airflow/dags/big_data_lab.py", line 39, in select_random_files
    print(os.listdir(location))
          ^^^^^^^^^^^^^^^^^^^^
FileNotFoundError: [Errno 2] No such file or directory: '/home/akranth/airflow/dag/www.ncei.noaa.gov/data/local-climatological-data/access/1903/'
[2024-03-10T13:49:43.723+0530] {taskinstance.py:1149} INFO - Marking task as FAILED. dag_id=data_fetch_pipeline_big_data, task_id=select_random_files, execution_date=20240303T110906, start_date=20240310T081943, end_date=20240310T081943
[2024-03-10T13:49:43.808+0530] {standard_task_runner.py:107} ERROR - Failed to execute job 26 for task select_random_files ([Errno 2] No such file or directory: '/home/akranth/airflow/dag/www.ncei.noaa.gov/data/local-climatological-data/access/1903/'; 5711)
[2024-03-10T13:49:43.849+0530] {local_task_job_runner.py:234} INFO - Task exited with return code 1
[2024-03-10T13:49:43.863+0530] {taskinstance.py:3309} INFO - 0 downstream tasks scheduled from follow-on schedule check
